Workbook

Sheet Sheet5
B2: Total operational GHG emissions from Russia's largets corporates in year 2024
B3: =SUM('Master data'!F2:F28) -> 697053.31 | C3: Millions CO2e
B5: Percentage of national GHG emissions associated with Russia's major corporates in 2024
B6: =B3/'Master data'!F30 -> 0.2706315
B8: Percentage of Globa GHG emissions associated with Russia's major corporates in 2024
B9: =(B3/1000000)/52.3 -> 0.013327979
B11: Total revenues from Russia's largets corporates in year 2024
B12: =SUM(Revenue!E2:E28) -> 50957.123 | C12: Billions RUB
B14: Percentage of national economic output associated with Russia's major corporates in 2024
B15: =B12/'Master data'!F34 -> 0.25478561
B17: Total workers employed by Russia's major corporates
B18: =Workers!B32 -> 3500000
B20: Percentage of national working age population employed by Russia's major corporates
B21: =B18/Workers!B34 -> 0.037234043

Sheet Master data
A1: ID | B1: Industry | C1: Company | D1: Owneship | E1: Website | F1: Operational emissions (thousands CO2e) | G1: Revenues (Billion URB)
A2: PT_01402 | B2: Chemicals | C2: PhosAgro | D2: Public | E2: https://www.phosagro.com | F2: =VLOOKUP('Master data'!A2,Emissions!$A$2:$J$28,10,FALSE) -> 5625.7 | G2: =VLOOKUP(A2,Revenue!$A$2:$E$28,5,FALSE) -> 507.689 | J2: {=_xlfn.UNIQUE(B2:B28)} -> Chemicals
A3: PT_00645 | B3: Conglomerates | C3: Cemros | D3: Private | E3: https://cemros.ru | F3: =VLOOKUP('Master data'!A3,Emissions!$A$2:$J$28,10,FALSE) -> 0 | G3: =VLOOKUP(A3,Revenue!$A$2:$E$28,5,FALSE) -> No public disclosure | J3: Conglomerates
A4: PT_02399 | B4: Construction & Engineering | C4: PIK Group | D4: Private | E4: https://pik-group.com | F4: =VLOOKUP('Master data'!A4,Emissions!$A$2:$J$28,10,FALSE) -> 0 | G4: =VLOOKUP(A4,Revenue!$A$2:$E$28,5,FALSE) -> 675.1 | J4: Construction & Engineering
A5: PT_02162 | B5: Food Production | C5: RusAgro | D5: Public | E5: https://www.rusagrogroup.ru | F5: =VLOOKUP('Master data'!A5,Emissions!$A$2:$J$28,10,FALSE) -> 0 | G5: =VLOOKUP(A5,Revenue!$A$2:$E$28,5,FALSE) -> 424 | J5: Food Production
A6: PT_01115 | B6: Food Retailers | C6: Magnit | D6: Public | E6: https://magnit-info.ru | F6: =VLOOKUP('Master data'!A6,Emissions!$A$2:$J$28,10,FALSE) -> 5460 | G6: =VLOOKUP(A6,Revenue!$A$2:$E$28,5,FALSE) -> 3043 | J6: Food Retailers
A7: PT_01958 | B7: Food Retailers | C7: X5 Retail Group | D7: Public | E7: https://www.x5.ru | F7: =VLOOKUP('Master data'!A7,Emissions!$A$2:$J$28,10,FALSE) -> 3461.577 | G7: =VLOOKUP(A7,Revenue!$A$2:$E$28,5,FALSE) -> 3908.047 | J7: IT Software & Services
A8: PT_02917 | B8: IT Software & Services | C8: Yandex | D8: Public | E8: https://yandex.com | F8: =VLOOKUP('Master data'!A8,Emissions!$A$2:$J$28,10,FALSE) -> 301.382 | G8: =VLOOKUP(A8,Revenue!$A$2:$E$28,5,FALSE) -> 798 | J8: Metals & Mining
A9: PT_02822 | B9: IT Software & Services | C9: VK | D9: Public | E9: https://vk.company | F9: =VLOOKUP('Master data'!A9,Emissions!$A$2:$J$28,10,FALSE) -> 35.504 | G9: =VLOOKUP(A9,Revenue!$A$2:$E$28,5,FALSE) -> 147.573 | J9: Oil & Gas
A10: PT_01298 | B10: Metals & Mining | C10: Nornickel | D10: Public | E10: https://www.nornickel.com | F10: =VLOOKUP('Master data'!A10,Emissions!$A$2:$J$28,10,FALSE) -> 8600 | G10: =VLOOKUP(A10,Revenue!$A$2:$E$28,5,FALSE) -> 1163.4 | J10: Passenger Transport
A11: PT_01307 | B11: Metals & Mining | C11: NLMK | D11: Private | E11: https://nlmk.com | F11: =VLOOKUP('Master data'!A11,Emissions!$A$2:$J$28,10,FALSE) -> 31471 | G11: =VLOOKUP(A11,Revenue!$A$2:$E$28,5,FALSE) -> 737.51301 | J11: Telecommunications
A12: PT_01567 | B12: Metals & Mining | C12: Severstal | D12: Public | E12: https://severstal.com | F12: =VLOOKUP('Master data'!A12,Emissions!$A$2:$J$28,10,FALSE) -> 23920 | G12: =VLOOKUP(A12,Revenue!$A$2:$E$28,5,FALSE) -> 829.779 | J12: Utilities
A13: PT_02084 | B13: Metals & Mining | C13: Rusal | D13: Public | E13: https://rusal.ru | F13: =VLOOKUP('Master data'!A13,Emissions!$A$2:$J$28,10,FALSE) -> 27306.032 | G13: =VLOOKUP(A13,Revenue!$A$2:$E$28,5,FALSE) -> 1121.5507
A14: PT_02248 | B14: Metals & Mining | C14: Polyus | D14: Public | E14: https://polyus.com | F14: =VLOOKUP('Master data'!A14,Emissions!$A$2:$J$28,10,FALSE) -> 2116.807 | G14: =VLOOKUP(A14,Revenue!$A$2:$E$28,5,FALSE) -> 7.343
A15: PT_00734 | B15: Oil & Gas | C15: Gazprom | D15: Public | E15: https://www.gazprom.com | F15: =VLOOKUP('Master data'!A15,Emissions!$A$2:$J$28,10,FALSE) -> 233640 | G15: =VLOOKUP(A15,Revenue!$A$2:$E$28,5,FALSE) -> 10714.686
A16: PT_01102 | B16: Oil & Gas | C16: Lukoil | D16: Public | E16: https://www.lukoil.com | F16: =VLOOKUP('Master data'!A16,Emissions!$A$2:$J$28,10,FALSE) -> 39844 | G16: =VLOOKUP(A16,Revenue!$A$2:$E$28,5,FALSE) -> 3046.944
A17: PT_01305 | B17: Oil & Gas | C17: Novatek | D17: Public | E17: https://www.novatek.ru | F17: =VLOOKUP('Master data'!A17,Emissions!$A$2:$J$28,10,FALSE) -> 9749.999 | G17: =VLOOKUP(A17,Revenue!$A$2:$E$28,5,FALSE) -> 1546
A18: PT_01498 | B18: Oil & Gas | C18: Rosneft | D18: Public | E18: https://www.rosneft.com | F18: =VLOOKUP('Master data'!A18,Emissions!$A$2:$J$28,10,FALSE) -> 80100 | G18: =VLOOKUP(A18,Revenue!$A$2:$E$28,5,FALSE) -> 10139
A19: PT_01701 | B19: Oil & Gas | C19: Surgutneftegas | D19: Public | E19: https://www.surgutneftegas.ru | F19: =VLOOKUP('Master data'!A19,Emissions!$A$2:$J$28,10,FALSE) -> 0 | G19: =VLOOKUP(A19,Revenue!$A$2:$E$28,5,FALSE) -> 923.3
A20: PT_01734 | B20: Oil & Gas | C20: Tatneft | D20: Public | E20: https://www.tatneft.ru | F20: =VLOOKUP('Master data'!A20,Emissions!$A$2:$J$28,10,FALSE) -> 13350 | G20: =VLOOKUP(A20,Revenue!$A$2:$E$28,5,FALSE) -> 2030.371
A21: PT_00032 | B21: Passenger Transport | C21: Aeroflot | D21: Public | E21: https://ir.aeroflot.com | F21: =VLOOKUP('Master data'!A21,Emissions!$A$2:$J$28,10,FALSE) -> 11283.6 | G21: =VLOOKUP(A21,Revenue!$A$2:$E$28,5,FALSE) -> 856.785
A22: PT_01501 | B22: Passenger Transport | C22: Russian Railways | D22: Government | E22: https://www.rzd.ru | F22: =VLOOKUP('Master data'!A22,Emissions!$A$2:$J$28,10,FALSE) -> 35600 | G22: =VLOOKUP(A22,Revenue!$A$2:$E$28,5,FALSE) -> 3296.3
A23: PT_01147 | B23: Telecommunications | C23: MegaFon | D23: Private | E23: https://moscow.megafon.ru | F23: =VLOOKUP('Master data'!A23,Emissions!$A$2:$J$28,10,FALSE) -> 0 | G23: =VLOOKUP(A23,Revenue!$A$2:$E$28,5,FALSE) -> 485.923
A24: PT_01191 | B24: Telecommunications | C24: MTS | D24: Public | E24: http://ir.mts.ru | F24: =VLOOKUP('Master data'!A24,Emissions!$A$2:$J$28,10,FALSE) -> 85217.317 | G24: =VLOOKUP(A24,Revenue!$A$2:$E$28,5,FALSE) -> 703.7
... A28: PT_02617 | B28: Utilities | C28: Mosvodokanal | D28: Government | E28: http://www.mosvodokanal.ru | F28: =VLOOKUP('Master data'!A28,Emissions!$A$2:$J$28,10,FALSE) -> 0 | G28: =VLOOKUP(A28,Revenue!$A$2:$E$28,5,FALSE) -> 89.217099
E30: Total territorial emissions in 2024 | F30: =2575654764/1000 -> 2575654.8
E31: Russia Greenhouse Gas (GHG) Emissions - Worldometer
E33: Total economic output in 2024
E34: Russian economy grew to $2.4T in 2024, says premier | F34: =200000 -> 200000 | G34: Billions
E36: Total GHG emisisons globaly in 2024
E37: EDGAR - The Emissions Database for Global Atmospheric Research | F37: 53.2 | G37: Gt
F38: No LULUCF

Sheet Emissions
A1: ID | B1: Industry | C1: Company | D1: Scope 1 emissions | E1: Scope 2 emissions (Location base) | F1: Scope 2 emissions (Market base) | G1: Scope 2 emissions (Undisclosed) | H1: Scope 2 (priority) | I1: Scope 1+2 (priority) | J1: Scope 1+2 (priority) in thousands tons | P1: Company refers to Climate policies | R1: Material emissions covered by transition plan | T1: Transition plan publication | V1: Transition plan updated in the last 3 years
A2: PT_00032 | B2: Passenger Transport | C2: Aeroflot | D2: 11243200 | G2: 40400 | H2: =G2 -> 40400 | I2: =D2+G2 -> 11283600 | J2: =I2/1000 -> 11283.6 | P2: Paris Agreement commitment | T2: None
A3: PT_00645 | B3: Conglomerates | C3: Cemros | J3: =I3/1000 -> 0 | T3: None
A4: PT_00734 | B4: Oil & Gas | C4: Gazprom | D4: 221160000 | G4: 12480000 | H4: =G4 -> 12480000 | I4: =D4+G4 -> 233640000 | J4: =I4/1000 -> 233640 | P4: Paris Agreement commitment, Regional policies | T4: None
A5: PT_00914 | B5: Utilities | C5: Inter RAO | D5: 78135000 | I5: =D5+G5 -> 78135000 | J5: =I5/1000 -> 78135 | T5: None
A6: PT_01102 | B6: Oil & Gas | C6: Lukoil | D6: 35584000 | E6: 4260000 | H6: =E6 -> 4260000 | I6: =D6+E6 -> 39844000 | J6: =I6/1000 -> 39844 | P6: Paris Agreement commitment | R6: Own operations | T6: Part of periodic reports | V6: TRUE
A7: PT_01115 | B7: Food Retailers | C7: Magnit | D7: 2330000 | G7: 3130000 | H7: =G7 -> 3130000 | I7: =D7+G7 -> 5460000 | J7: =I7/1000 -> 5460 | R7: Own operations | T7: Part of periodic reports
A8: PT_01147 | B8: Telecommunications | C8: MegaFon | J8: =I8/1000 -> 0 | T8: None
A9: PT_01191 | B9: Telecommunications | C9: MTS | D9: 4656616 | E9: 80560701 | H9: =E9 -> 80560701 | I9: =D9+E9 -> 85217317 | J9: =I9/1000 -> 85217.317 | T9: None
A10: PT_01298 | B10: Metals & Mining | C10: Nornickel | D10: 8200000 | E10: 400000 | H10: =E10 -> 400000 | I10: =D10+E10 -> 8600000 | J10: =I10/1000 -> 8600 | P10: Regional policies | T10: None
A11: PT_01305 | B11: Oil & Gas | C11: Novatek | D11: 9571891 | E11: 178108 | H11: =E11 -> 178108 | I11: =D11+E11 -> 9749999 | J11: =I11/1000 -> 9749.999 | P11: Paris Agreement commitment, Regional policies | R11: Own operations | T11: Part of periodic reports | V11: TRUE
A12: PT_01307 | B12: Metals & Mining | C12: NLMK | D12: 29578000 | E12: 1893000 | F12: 389000 | H12: =E12 -> 1893000 | I12: =D12+E12 -> 31471000 | J12: =I12/1000 -> 31471 | R12: Own operations, Upstream, Downstream | T12: Part of periodic reports | V12: TRUE
A13: PT_01402 | B13: Chemicals | C13: PhosAgro | D13: 4716300 | G13: 909400 | H13: =G13 -> 909400 | I13: =D13+G13 -> 5625700 | J13: =I13/1000 -> 5625.7 | R13: Own operations, Upstream, Downstream | T13: Comprehensive standalone document
A14: PT_01498 | B14: Oil & Gas | C14: Rosneft | D14: 65800000 | G14: 14300000 | H14: =G14 -> 14300000 | I14: =D14+G14 -> 80100000 | J14: =I14/1000 -> 80100 | P14: Paris Agreement commitment | R14: Own operations | T14: Part of periodic reports | V14: TRUE
A15: PT_01500 | B15: Utilities | C15: Rosseti | D15: 266000 | I15: =D15+G15 -> 266000 | J15: =I15/1000 -> 266 | P15: Regional policies | T15: None
A16: PT_01501 | B16: Passenger Transport | C16: Russian Railways | D16: 10200000 | G16: 25400000 | H16: =G16 -> 25400000 | I16: =D16+G16 -> 35600000 | J16: =I16/1000 -> 35600 | R16: Own operations | T16: Part of periodic reports
A17: PT_01502 | B17: Telecommunications | C17: Rostelecom | D17: 138311 | G17: 1431081 | H17: =G17 -> 1431081 | I17: =D17+G17 -> 1569392 | J17: =I17/1000 -> 1569.392 | T17: None
A18: PT_01567 | B18: Metals & Mining | C18: Severstal | D18: 23030000 | E18: 890000 | F18: 890000 | H18: =E18 -> 890000 | I18: =D18+E18 -> 23920000 | J18: =I18/1000 -> 23920 | P18: Paris Agreement commitment | R18: Own operations, Upstream, Downstream | T18: Part of periodic reports | V18: TRUE
A19: PT_01701 | B19: Oil & Gas | C19: Surgutneftegas | J19: =I19/1000 -> 0 | T19: None
A20: PT_01734 | B20: Oil & Gas | C20: Tatneft | D20: 8180000 | G20: 5170000 | H20: =G20 -> 5170000 | I20: =D20+G20 -> 13350000 | J20: =I20/1000 -> 13350 | R20: Own operations | T20: Part of periodic reports
A21: PT_01958 | B21: Food Retailers | C21: X5 Retail Group | D21: 1745875 | E21: 1715702 | F21: 2349672 | H21: =G21 -> 0 | I21: =D21+E21 -> 3461577 | J21: =I21/1000 -> 3461.577 | R21: Own operations, Upstream, Downstream | T21: Part of periodic reports | V21: TRUE
A22: PT_02084 | B22: Metals & Mining | C22: Rusal | D22: 26151217 | G22: 1154815 | H22: =G22 -> 1154815 | I22: =D22+G22 -> 27306032 | J22: =I22/1000 -> 27306.032 | P22: Paris Agreement commitment | R22: Own operations | T22: Part of periodic reports | V22: TRUE
A23: PT_02162 | B23: Food Production | C23: RusAgro | H23: =G23 -> 0 | I23: =D23+G23 -> 0 | J23: =I23/1000 -> 0 | T23: None
A24: PT_02248 | B24: Metals & Mining | C24: Polyus | D24: 1310000 | E24: 806807 | F24: 7300 | H24: =E24 -> 806807 | I24: =D24+E24 -> 2116807 | J24: =I24/1000 -> 2116.807 | P24: Paris Agreement commitment | R24: Own operations, Upstream, Downstream | T24: Comprehensive standalone document
A25: PT_02399 | B25: Construction & Engineering | C25: PIK Group | H25: =G25 -> 0 | I25: =D25+G25 -> 0 | J25: =I25/1000 -> 0 | T25: None
A26: PT_02617 | B26: Utilities | C26: Mosvodokanal | H26: =G26 -> 0 | I26: =D26+G26 -> 0 | J26: =I26/1000 -> 0 | T26: None
A27: PT_02822 | B27: IT Software & Services | C27: VK | D27: 798 | G27: 34706 | H27: =G27 -> 34706 | I27: =D27+G27 -> 35504 | J27: =I27/1000 -> 35.504 | T27: None
A28: PT_02917 | B28: IT Software & Services | C28: Yandex | D28: 98984 | E28: 202398 | H28: =E28 -> 202398 | I28: =D28+E28 -> 301382 | J28: =I28/1000 -> 301.382 | T28: None
I30: =SUM(I2:I28)/1000000000 -> 0.69705331
H31: Total
H32: =2.3 -> 2.3
H33: =I30/H32 -> 0.30306666

Sheet Revenue
A1: ID | B1: Industry | C1: Company | D1: Revenue | E1: Revenue in Billions | F1: Revenue (currency)
A2: PT_00032 | B2: Passenger Transport | C2: Aeroflot | D2: 856785000000 | E2: =D2/1000000000 -> 856.785 | F2: RUB
A3: PT_00645 | B3: Conglomerates | C3: Cemros | E3: No public disclosure
A4: PT_00734 | B4: Oil & Gas | C4: Gazprom | D4: 10714686000000 | E4: =D4/1000000000 -> 10714.686 | F4: RUB
A5: PT_00914 | B5: Utilities | C5: Inter RAO | D5: 1548447000000 | E5: =D5/1000000000 -> 1548.447 | F5: RUB
A6: PT_01102 | B6: Oil & Gas | C6: Lukoil | D6: 3046944000000 | E6: =D6/1000000000 -> 3046.944 | F6: RUB
A7: PT_01115 | B7: Food Retailers | C7: Magnit | D7: 3043000000000 | E7: =D7/1000000000 -> 3043 | F7: RUB
A8: PT_01147 | B8: Telecommunications | C8: MegaFon | D8: 485923000000 | E8: =D8/1000000000 -> 485.923 | F8: RUB
A9: PT_01191 | B9: Telecommunications | C9: MTS | D9: 703700000000 | E9: =D9/1000000000 -> 703.7 | F9: RUB
A10: PT_01298 | B10: Metals & Mining | C10: Nornickel | D10: 1163400000000 | E10: =D10/1000000000 -> 1163.4 | F10: RUB
A11: PT_01305 | B11: Oil & Gas | C11: Novatek | D11: 1546000000000 | E11: =D11/1000000000 -> 1546 | F11: RUB
A12: PT_01307 | B12: Metals & Mining | C12: NLMK | D12: 737513007000 | E12: =D12/1000000000 -> 737.51301 | F12: RUB
A13: PT_01402 | B13: Chemicals | C13: PhosAgro | D13: 507689000000 | E13: =D13/1000000000 -> 507.689 | F13: RUB
A14: PT_01498 | B14: Oil & Gas | C14: Rosneft | D14: 10139000000000 | E14: =D14/1000000000 -> 10139 | F14: RUB
A15: PT_01500 | B15: Utilities | C15: Rosseti | D15: 1505655000000 | E15: =D15/1000000000 -> 1505.655 | F15: RUB
... A28: PT_02917 | B28: IT Software & Services | C28: Yandex | D28: 798000000000 | E28: =D28/1000000000 -> 798 | F28: RUB
D30: =SUM(D2:D28) -> 50957122782000
D32: 200000000000000
D33: =D30/D32 -> 0.25478561

Sheet GHG disclosure
A1: ID | B1: Industry | C1: Company | D1: Methedology reported | F1: Emissions discolure per category in 2024
A2: PT_01402 | B2: Chemicals | C2: PhosAgro | F2: S1 | G2: S2 | H2: S1+2 | I2: S3.01 | J2: S3.02 | K2: S3.03 | L2: S3.04 | M2: S3.05 | N2: S3.06 | O2: S3.07 | P2: S3.08 | Q2: S3.09 | R2: S3.10 | S2: S3.11 | T2: S3.12 | U2: S3.13 | V2: S3.14 | W2: S3.15 | X2: S3
A3: PT_00645 | B3: Conglomerates | C3: Cemros
A4: PT_02399 | B4: Construction & Engineering | C4: PIK Group | F4: S3.15
A5: PT_02162 | B5: Food Production | C5: RusAgro | F5: S3.15
A6: PT_01115 | B6: Food Retailers | C6: Magnit | F6: S1 | G6: S2 | H6: S1+2 | I6: S3.02 | J6: S3.03 | K6: S3.04 | L6: S3.05 | M6: S3.06 | N6: S3.07 | O6: S3.08 | P6: S3.09 | Q6: S3.10 | R6: S3.11 | S6: S3.12 | T6: S3.13 | U6: S3.14 | V6: S3.15
A7: PT_01958 | B7: Food Retailers | C7: X5 Retail Group | F7: S1 | G7: S2.MB | H7: S2.LB | I7: S2 | J7: S1+2 | K7: S3.01 | L7: S3.02 | M7: S3.03 | N7: S3.04 | O7: S3.05 | P7: S3.06 | Q7: S3.07 | R7: S3.08 | S7: S3.09 | T7: S3.10 | U7: S3.11 | V7: S3.12 | W7: S3.13 | X7: S3.14 | Y7: S3.15 | Z7: S3
A8: PT_02917 | B8: IT Software & Services | C8: Yandex | F8: S1 | G8: S2.LB | H8: S2 | I8: S1+2 | J8: S3.01 | K8: S3.02 | L8: S3.03 | M8: S3.04 | N8: S3.05 | O8: S3.07 | P8: S3.09 | Q8: S3.10 | R8: S3.11 | S8: S3.13 | T8: S3.14 | U8: S3.15
A9: PT_02822 | B9: IT Software & Services | C9: VK | F9: S1 | G9: S2 | H9: S1+2 | I9: S3.01 | J9: S3.02 | K9: S3.03 | L9: S3.04 | M9: S3.05 | N9: S3.07 | O9: S3.09 | P9: S3.10 | Q9: S3.11 | R9: S3.12 | S9: S3.13 | T9: S3.14 | U9: S3.15
A10: PT_01298 | B10: Metals & Mining | C10: Nornickel | F10: S1 | G10: S2.LB | H10: S2 | I10: S1+2 | J10: S3.01 | K10: S3.02 | L10: S3.03 | M10: S3.04 | N10: S3.05 | O10: S3.06 | P10: S3.07 | Q10: S3.08 | R10: S3.09 | S10: S3.10 | T10: S3.11 | U10: S3.12 | V10: S3.13 | W10: S3.14 | X10: S3.15 | Y10: S3
A11: PT_01307 | B11: Metals & Mining | C11: NLMK | F11: S1 | G11: S2.MB | H11: S2.LB | I11: S2 | J11: S1+2 | K11: S3.01 | L11: S3.02 | M11: S3.03 | N11: S3.04 | O11: S3.05 | P11: S3.06 | Q11: S3.07 | R11: S3.08 | S11: S3.09 | T11: S3.10 | U11: S3.11 | V11: S3.12 | W11: S3.13 | X11: S3.14 | Y11: S3.15 | Z11: S3
A12: PT_01567 | B12: Metals & Mining | C12: Severstal | F12: S1 | G12: S2.MB | H12: S2.LB | I12: S2 | J12: S1+2 | K12: S3.01 | L12: S3.02 | M12: S3.03 | N12: S3.04 | O12: S3.05 | P12: S3.06 | Q12: S3.07 | R12: S3.08 | S12: S3.09 | T12: S3.10 | U12: S3.11 | V12: S3.12 | W12: S3.13 | X12: S3.14 | Y12: S3.15 | Z12: S3
A13: PT_02084 | B13: Metals & Mining | C13: Rusal | F13: S1 | G13: S2 | H13: S1+2 | I13: S3.02 | J13: S3.03 | K13: S3.04 | L13: S3.05 | M13: S3.06 | N13: S3.07 | O13: S3.08 | P13: S3.09 | Q13: S3.10 | R13: S3.11 | S13: S3.12 | T13: S3.13 | U13: S3.14 | V13: S3.15 | W13: S3
A14: PT_02248 | B14: Metals & Mining | C14: Polyus | F14: S1 | G14: S2.MB | H14: S2.LB | I14: S2 | J14: S1+2 | K14: S3.01 | L14: S3.02 | M14: S3.03 | N14: S3.04 | O14: S3.05 | P14: S3.06 | Q14: S3.07 | R14: S3.08 | S14: S3.09 | T14: S3.10 | U14: S3.11 | V14: S3.12 | W14: S3.13 | X14: S3.14 | Y14: S3.15 | Z14: S3
A15: PT_00734 | B15: Oil & Gas | C15: Gazprom | F15: S1 | G15: S2 | H15: S1+2 | I15: S3.01 | J15: S3.02 | K15: S3.03 | L15: S3.04 | M15: S3.05 | N15: S3.06 | O15: S3.07 | P15: S3.08 | Q15: S3.09 | R15: S3.10 | S15: S3.12 | T15: S3.13 | U15: S3.14 | V15: S3.15
A16: PT_01102 | B16: Oil & Gas | C16: Lukoil | F16: S1 | G16: S2.LB | H16: S2 | I16: S1+2 | J16: S3.01 | K16: S3.02 | L16: S3.03 | M16: S3.04 | N16: S3.05 | O16: S3.07 | P16: S3.08 | Q16: S3.09 | R16: S3.10 | S16: S3.11 | T16: S3.12 | U16: S3.13 | V16: S3.14 | W16: S3.15 | X16: S3
A17: PT_01305 | B17: Oil & Gas | C17: Novatek | F17: S1 | G17: S2.LB | H17: S2 | I17: S1+2 | J17: S3.01 | K17: S3.02 | L17: S3.03 | M17: S3.04 | N17: S3.05 | O17: S3.06 | P17: S3.07 | Q17: S3.08 | R17: S3.09 | S17: S3.10 | T17: S3.11 | U17: S3.12 | V17: S3.13 | W17: S3.14 | X17: S3.15 | Y17: S3
A18: PT_01498 | B18: Oil & Gas | C18: Rosneft | F18: S1 | G18: S2 | H18: S1+2 | I18: S3.01 | J18: S3.02 | K18: S3.03 | L18: S3.04 | M18: S3.05 | N18: S3.06 | O18: S3.07 | P18: S3.08 | Q18: S3.09 | R18: S3.10 | S18: S3.12 | T18: S3.13 | U18: S3.14 | V18: S3.15
A19: PT_01701 | B19: Oil & Gas | C19: Surgutneftegas
A20: PT_01734 | B20: Oil & Gas | C20: Tatneft | F20: S1 | G20: S2 | H20: S1+2 | I20: S3.01 | J20: S3.02 | K20: S3.03 | L20: S3.05 | M20: S3.07 | N20: S3.08 | O20: S3.12 | P20: S3.13 | Q20: S3.14 | R20: S3.15 | S20: S3
A21: PT_00032 | B21: Passenger Transport | C21: Aeroflot | F21: S1 | G21: S2 | H21: S1+2 | I21: S3.02 | J21: S3.06 | K21: S3.07 | L21: S3.08 | M21: S3.09 | N21: S3.10 | O21: S3.11 | P21: S3.12 | Q21: S3.13 | R21: S3.14 | S21: S3.15 | T21: S3
A22: PT_01501 | B22: Passenger Transport | C22: Russian Railways | F22: S1 | G22: S2 | H22: S1+2 | I22: S3.01 | J22: S3.02 | K22: S3.03 | L22: S3.05 | M22: S3.06 | N22: S3.07 | O22: S3.08 | P22: S3.09 | Q22: S3.10 | R22: S3.11 | S22: S3.12 | T22: S3.13 | U22: S3.14 | V22: S3.15
A23: PT_01147 | B23: Telecommunications | C23: MegaFon
A24: PT_01191 | B24: Telecommunications | C24: MTS | F24: S1 | G24: S2.LB | H24: S2 | I24: S1+2 | J24: S3
A25: PT_01502 | B25: Telecommunications | C25: Rostelecom | F25: S1 | G25: S2 | H25: S1+2 | I25: S3.02 | J25: S3.03 | K25: S3.04 | L25: S3.05 | M25: S3.06 | N25: S3.07 | O25: S3.09 | P25: S3.10 | Q25: S3
A26: PT_00914 | B26: Utilities | C26: Inter RAO | F26: S1
A27: PT_01500 | B27: Utilities | C27: Rosseti | F27: S1 | G27: S3.01 | H27: S3.02 | I27: S3.04 | J27: S3.05 | K27: S3.06 | L27: S3.07 | M27: S3.08 | N27: S3.09 | O27: S3.10 | P27: S3.12 | Q27: S3.13 | R27: S3.14 | S27: S3.15
A28: PT_02617 | B28: Utilities | C28: Mosvodokanal
F29: =(27-COUNTBLANK(F2:F28))/27 -> 0.85185185
F31: Category | I31: % reporting | K31: # reporting
F33: S3.01 | G33: Purchased goods and services | I33: =K33/27*100 -> 55.555556 | K33: =COUNTIF($F$2:$Z$27,F33) -> 15
F34: S3.02 | G34: Capital goods | I34: =K34/27*100 -> 70.37037 | K34: =COUNTIF($F$2:$Z$27,F34) -> 19
F35: S3.03 | G35: Fuel- and energy-related activities | I35: =K35/27*100 -> 62.962963 | K35: =COUNTIF($F$2:$Z$27,F35) -> 17
F36: S3.04 | G36: Upstream transportation and distribution | I36: =K36/27*100 -> 59.259259 | K36: =COUNTIF($F$2:$Z$27,F36) -> 16
F37: S3.05 | G37: Waste generated in operations | I37: =K37/27*100 -> 66.666667 | K37: =COUNTIF($F$2:$Z$27,F37) -> 18
F38: S3.06 | G38: Business travel | I38: =K38/27*100 -> 55.555556 | K38: =COUNTIF($F$2:$Z$27,F38) -> 15
F39: S3.07 | G39: Employee commuting | I39: =K39/27*100 -> 70.37037 | K39: =COUNTIF($F$2:$Z$27,F39) -> 19
F40: S3.08 | G40: Upstream leased assets | I40: =K40/27*100 -> 59.259259 | K40: =COUNTIF($F$2:$Z$27,F40) -> 16
F42: S1 | G42: Scope 1 | I42: =K42/27*100 -> 77.777778 | K42: =COUNTIF($F$2:$Z$27,F42) -> 21
F43: S2 | G43: Scope 2 (any) | I43: =K43/27*100 -> 70.37037 | K43: =COUNTIF($F$2:$Z$27,F43) -> 19
...

Sheet Target overview
A2: PT_02917 | B2: Yandex | C2: S1+2 | D2: Near-term | F2: 2023 | H2: Undisclosed | M2: IT Software & Services
A3: PT_02917 | B3: Yandex | C3: S1+2 | D3: Long-term | F3: 2023 | H3: Undisclosed | M3: IT Software & Services | R3: Any near-term S1+2 | S3: Any near-term S3
A4: PT_02917 | B4: Yandex | C4: S3 | D4: Near-term | F4: 2023 | H4: Undisclosed | M4: IT Software & Services | R4: 12 | S4: 1
A5: PT_02917 | B5: Yandex | C5: S3 | D5: Long-term | F5: 2023 | H5: Undisclosed | M5: IT Software & Services | R5: =R4/27 -> 0.44444444
A6: PT_01958 | B6: X5 Retail Group | C6: S1+2 | D6: Near-term | E6: 2019 | F6: 2024 | G6: 2030 | H6: Valid | I6: Goal to 2030 Reduce GHG emissions (Scope 1 and 2) per sqm of selling space by 30% compared with 2019 through improved energy efficiency. | J6: Intensity | K6: Not validated | L6: 0.3 | M6: Food Retailers
A7: PT_01958 | B7: X5 Retail Group | C7: S1+2 | D7: Long-term | F7: 2024 | H7: Undisclosed | M7: Food Retailers
A8: PT_01958 | B8: X5 Retail Group | C8: S3 | D8: Near-term | F8: 2024 | H8: Undisclosed | M8: Food Retailers | R8: Valid Near-term S1+2 | S8: Valid Long-term S1+2 | T8: Valid Near-term S3 | U8: Valid Long-term S3
A9: PT_01958 | B9: X5 Retail Group | C9: S3 | D9: Long-term | F9: 2024 | H9: Undisclosed | M9: Food Retailers | Q9: Valid targets | R9: =COUNTIFS($H$2:$H$109,"Valid",$D$2:$D$109,"Near-term",$C$2:$C$109,"S1+2") -> 10 | S9: =COUNTIFS($H$2:$H$109,"Valid",$D$2:$D$109,"Long-term",$C$2:$C$109,"S1+2") -> 4 | T9: =COUNTIFS($H$2:$H$109,"Valid",$D$2:$D$109,"Near-term",$C$2:$C$109,"S3") -> 1 | U9: =COUNTIFS($H$2:$H$109,"Valid",$D$2:$D$109,"Long-term",$C$2:$C$109,"S3") -> 0
A10: PT_02822 | B10: VK | C10: S1+2 | D10: Near-term | F10: 2024 | H10: Undisclosed | M10: IT Software & Services | Q10: % of total | R10: =R9/27 -> 0.37037037 | S10: =S9/27 -> 0.14814815 | T10: =T9/27 -> 0.037037037 | U10: =U9/27 -> 0
A11: PT_02822 | B11: VK | C11: S1+2 | D11: Long-term | F11: 2024 | H11: Undisclosed | M11: IT Software & Services | Q11: Average ambition | R11: =AVERAGE(L6,L14,L22,L26,L30,L46,L50,L58,L62,L90) -> 0.206
A12: PT_02822 | B12: VK | C12: S3 | D12: Near-term | F12: 2024 | H12: Undisclosed | M12: IT Software & Services
A13: PT_02822 | B13: VK | C13: S3 | D13: Long-term | F13: 2024 | H13: Undisclosed | M13: IT Software & Services
A14: PT_01734 | B14: Tatneft | C14: S1+2 | D14: Near-term | E14: 2021 | F14: 2024 | G14: 2030 | H14: Valid | I14: Reduce scopes 1+2 GHG Emissions by 14% and 30% by 2025 and 2030, respectively. | J14: Absolute | K14: Not validated | L14: 0.3 | M14: Oil & Gas
A15: PT_01734 | B15: Tatneft | C15: S1+2 | D15: Long-term | F15: 2024 | H15: Undisclosed | M15: Oil & Gas
A16: PT_01734 | B16: Tatneft | C16: S3 | D16: Near-term | F16: 2024 | H16: Undisclosed | M16: Oil & Gas
A17: PT_01734 | B17: Tatneft | C17: S3 | D17: Long-term | F17: 2024 | H17: Undisclosed | M17: Oil & Gas | Q17: {=_xlfn.UNIQUE(M2:M109)} -> IT Software & Services | R17: =COUNTIFS($H$2:$H$109,"Valid",$D$2:$D$109,"Near-term",$C$2:$C$109,"S1+2",$M$2:$M$109,Q17) -> 0 | S17: 2 | T17: =R17/S17 -> 0
A18: PT_01701 | B18: Surgutneftegas | C18: S1+2 | D18: Near-term | F18: 2024 | H18: Undisclosed | M18: Oil & Gas | Q18: Food Retailers | R18: =COUNTIFS($H$2:$H$109,"Valid",$D$2:$D$109,"Near-term",$C$2:$C$109,"S1+2",$M$2:$M$109,Q18) -> 1 | S18: 2 | T18: =R18/S18 -> 0.5
A19: PT_01701 | B19: Surgutneftegas | C19: S1+2 | D19: Long-term | F19: 2024 | H19: Undisclosed | M19: Oil & Gas | Q19: Oil & Gas | R19: =COUNTIFS($H$2:$H$109,"Valid",$D$2:$D$109,"Near-term",$C$2:$C$109,"S1+2",$M$2:$M$109,Q19) -> 4 | S19: 6 | T19: =R19/S19 -> 0.66666667
A20: PT_01701 | B20: Surgutneftegas | C20: S3 | D20: Near-term | F20: 2024 | H20: Undisclosed | M20: Oil & Gas | Q20: Metals & Mining | R20: =COUNTIFS($H$2:$H$109,"Valid",$D$2:$D$109,"Near-term",$C$2:$C$109,"S1+2",$M$2:$M$109,Q20) -> 3 | S20: 5 | T20: =R20/S20 -> 0.6 | U20: =AVERAGE(T17:T18,T21:T27) -> 0.22222222
A21: PT_01701 | B21: Surgutneftegas | C21: S3 | D21: Long-term | F21: 2024 | H21: Undisclosed | M21: Oil & Gas | Q21: Passenger Transport | R21: =COUNTIFS($H$2:$H$109,"Valid",$D$2:$D$109,"Near-term",$C$2:$C$109,"S1+2",$M$2:$M$109,Q21) -> 1 | S21: 2 | T21: =R21/S21 -> 0.5
A22: PT_01567 | B22: Severstal | C22: S1+2 | D22: Near-term | E22: 2020 | F22: 2024 | G22: 2030 | H22: Valid | I22: Severstal’s Decarbonisation Strategy sets forth voluntary obligations to reduce the CO2 intensity of steel production by 3% in 2024 (short-term goal) and by 10% in 2030 (mid-term goal) against the 2020 baseline. | J22: Intensity | L22: 0.1 | M22: Metals & Mining | Q22: Food Production | R22: =COUNTIFS($H$2:$H$109,"Valid",$D$2:$D$109,"Near-term",$C$2:$C$109,"S1+2",$M$2:$M$109,Q22) -> 0 | S22: 1 | T22: =R22/S22 -> 0
A23: PT_01567 | B23: Severstal | C23: S1+2 | D23: Long-term | F23: 2024 | H23: Undisclosed | M23: Metals & Mining | Q23: Telecommunications | R23: =COUNTIFS($H$2:$H$109,"Valid",$D$2:$D$109,"Near-term",$C$2:$C$109,"S1+2",$M$2:$M$109,Q23) -> 0 | S23: 3 | T23: =R23/S23 -> 0
A24: PT_01567 | B24: Severstal | C24: S3 | D24: Near-term | F24: 2024 | H24: Undisclosed | M24: Metals & Mining | Q24: Utilities | R24: =COUNTIFS($H$2:$H$109,"Valid",$D$2:$D$109,"Near-term",$C$2:$C$109,"S1+2",$M$2:$M$109,Q24) -> 0 | S24: 3 | T24: =R24/S24 -> 0
A25: PT_01567 | B25: Severstal | C25: S3 | D25: Long-term | F25: 2024 | H25: Undisclosed | M25: Metals & Mining | Q25: Construction & Engineering | R25: =COUNTIFS($H$2:$H$109,"Valid",$D$2:$D$109,"Near-term",$C$2:$C$109,"S1+2",$M$2:$M$109,Q25) -> 0 | S25: 1 | T25: =R25/S25 -> 0
A26: PT_01501 | B26: Russian Railways | C26: S1+2 | D26: Near-term | E26: 2019 | F26: 2024 | G26: 2030 | H26: Valid | I26: Target GHG emissions per unit of transportation2, kg of CO2 equivalent / 10,000 gross virtual tkm 30 Innovative scenario –7.9%. 2019 baseyear. | J26: Intensity | K26: Not validated | L26: 0.08 | M26: Passenger Transport | Q26: Chemicals | R26: =COUNTIFS($H$2:$H$109,"Valid",$D$2:$D$109,"Near-term",$C$2:$C$109,"S1+2",$M$2:$M$109,Q26) -> 1 | S26: 1 | T26: =R26/S26 -> 1
A27: PT_01501 | B27: Russian Railways | C27: S1+2 | D27: Long-term | E27: 2019 | F27: 2024 | G27: 2035 | H27: Valid | I27: Target GHG emissions per unit of transportation2, kg of CO2 equivalent / 10,000 gross virtual tkm 2035 –11% 2019 baseyear. | J27: Intensity | K27: Not validated | L27: 0.11 | M27: Passenger Transport | Q27: Conglomerates | R27: =COUNTIFS($H$2:$H$109,"Valid",$D$2:$D$109,"Near-term",$C$2:$C$109,"S1+2",$M$2:$M$109,Q27) -> 0 | S27: 1 | T27: =R27/S27 -> 0
A28: PT_01501 | B28: Russian Railways | C28: S3 | D28: Near-term | F28: 2024 | H28: Undisclosed | M28: Passenger Transport | S28: =SUM(S17:S27) -> 27
A29: PT_01501 | B29: Russian Railways | C29: S3 | D29: Long-term | F29: 2024 | H29: Undisclosed | M29: Passenger Transport
A30: PT_02084 | B30: Rusal | C30: S1+2 | D30: Near-term | E30: 2018 | F30: 2024 | G30: 2035 | H30: Valid | I30: RUSAL 's targets: By 2035 reduce specific GHG emissions from all production facilities (processes under the Company's operational control) for Scopes 1 and 2 by 23% (without regard to offsetting measures) per tonne of metal compared to the 2018 baseline | J30: Intensity | K30: Not validated | L30: 0.23 | M30: Metals & Mining
A31: PT_02084 | B31: Rusal | C31: S1+2 | D31: Long-term | E31: 2018 | F31: 2024 | G31: 2050 | H31: Valid | I31: By 2050: Reduce GHG emissions from production by electrolysis for Scopes 1 and 2 by 99% (without regard to offsetting measures) per tonne of metal compared to the 2018 baseline. | J31: Intensity | K31: Not validated | L31: 0.99 | M31: Metals & Mining
A32: PT_02084 | B32: Rusal | C32: S3 | D32: Near-term | F32: 2024 | H32: Undisclosed | M32: Metals & Mining
A33: PT_02084 | B33: Rusal | C33: S3 | D33: Long-term | F33: 2024 | H33: Undisclosed | M33: Metals & Mining
A34: PT_02162 | B34: RusAgro | C34: S1+2 | D34: Near-term | F34: 2024 | H34: Undisclosed | M34: Food Production
A35: PT_02162 | B35: RusAgro | C35: S1+2 | D35: Long-term | F35: 2024 | H35: Undisclosed | M35: Food Production
A36: PT_02162 | B36: RusAgro | C36: S3 | D36: Near-term | F36: 2024 | H36: Undisclosed | M36: Food Production
A37: PT_02162 | B37: RusAgro | C37: S3 | D37: Long-term | F37: 2024 | H37: Undisclosed | M37: Food Production
A38: PT_01502 | B38: Rostelecom | C38: S1+2 | D38: Near-term | F38: 2023 | H38: Undisclosed | M38: Telecommunications
A39: PT_01502 | B39: Rostelecom | C39: S1+2 | D39: Long-term | F39: 2023 | H39: Undisclosed | M39: Telecommunications
A40: PT_01502 | B40: Rostelecom | C40: S3 | D40: Near-term | F40: 2023 | H40: Undisclosed | M40: Telecommunications
A41: PT_01502 | B41: Rostelecom | C41: S3 | D41: Long-term | F41: 2023 | H41: Undisclosed | M41: Telecommunications
...

Sheet Workers
A1: Company | B1: Employees | C1: Data Year | D1: Notes
A2: PhosAgro | B2: ~21,600 | C2: 2024 | D2: PitchBook; official sites show 10,000+
A3: Cemros | B3: ~13,000 | C3: 2025 | D3: Reuters Oct 2025 (company spokesman)
A4: PIK Group | B4: ~13,000 | C4: 2022 | D4: Wikipedia; parent entity ~1,700
A5: RusAgro | B5: ~15,000–20,000 | C5: 2024 | D5: Est. based on group scale; not publicly disclosed
A6: Magnit | B6: 386,000 | C6: 2025 | D6: Official company website (magnit.com)
A7: X5 Retail Group | B7: ~416,000–432,000 | C7: 2024 | D7: GlobalData / PitchBook
A8: Yandex | B8: ~28,000 | C8: 2024 | D8: ~25,127 Russian entity + international staff
A9: VK | B9: ~5,000–10,000 | C9: 2024 | D9: Privately held; limited public disclosure
A10: Nornickel | B10: ~78,700 | C10: 2024 | D10: 2024 Annual Report (avg. headcount)
A11: NLMK | B11: ~44,400–53,000 | C11: 2023 | D11: Sustainability Report 2023 (44,400); older ~53,000
A12: Severstal | B12: ~26,600 | C12: 2023 | D12: PitchBook
... A28: Mosvodokanal | B28: ~14,000–17,000 | C28: 2024 | D28: Moscow water utility; limited public data
B29: =COUNTA(B2:B28) -> 27 | C29: 27 companies
B31: Approximate total
B32: 3500000 | C32: workers
B33: Total russia population in working age
B34: 94000000
B35: World Economics | Economic data for the benefit of investors

Sheet Lukoil
A1: Main reporting sources
A2: Sustainbility report | B2: CDP report | D2: Note on current sustainability disclosure | E2: Source
A3: Sustainability Report | B3: Ratings and initiatives | D3: Lukoil has yet to publish its 2025 Sustainability report but its expected to do so in Jully 2026. | E3: Sustainable Development Approach
A6: Emissions profile and disclosure
A7: Category | B7: Tons CO2e | C7: Year | D7: Disclosure framework | E7: Verification | G7: S1+2 share | H7: S3 share
A8: Scope 1 | B8: 35584000 | C8: 2024 | D8: GHG protocol | E8: External limited assurance | G8: =B10/B14 -> 0.11006275 | H8: =B13/B14 -> 0.88993725
A9: Scope 2 | B9: 4260000 | C9: 2024 | D9: GHG protocol | E9: External limited assurance
A10: Scope 1+2 | B10: =SUM(B8:B9) -> 39844000 | C10: 2024 | D10: GHG protocol
A11: Downstream Transportation and Distribution | B11: 3834906 | C11: 2024 | D11: GHG protocol
A12: Use of sold products | B12: 318332757 | C12: 2024 | D12: GHG protocol | E12: External limited assurance
A13: Scope 3 | B13: =SUM(B11:B12) -> 322167663 | C13: 2024 | D13: GHG protocol | E13: External limited assurance
A14: Total 1+2+3 | B14: =SUM(B10,B13) -> 362011663 | C14: 2024 | D14: GHG protocol
A16: Climate targets
A17: Company | B17: Scope | C17: Base year | D17: Target tear | E17: % reduction | F17: Base emissions | G17: Target emissions | H17: Target type | I17: SBTi validation | J17: Scorable | K17: Activity unit | L17: Intensity unit | M17: Target wording
A18: Lukoil | B18: S1+2 | C18: 2017 | D18: 2030 | E18: 0.2 | F18: 48397000 | G18: 38717600 | H18: Absolute | I18: Not validated | J18: Valid | K18: metric tons | M18: To reduce controlled GHG emissions (Scope 1 + Scope 2) by 2030 at least by 20% compared to the 2017 level2: -17.7%.
A19: Lukoil | B19: S1+2 | D19: 2050 | I19: Not validated | J19: Undisclosed | K19: metric tons | M19: reaching net-zero greenhouse gas emissions (Scope 1 and Scope 2) by or before 2050.
A20: Lukoil | B20: S3 | J20: Undisclosed | K20: metric tons
A21: Lukoil | B21: S3 | J21: Undisclosed | K21: metric tons
A24: Target appraisal
B25: Observed change per year in Scope 1+2 emissions | D25: Required reductions of scope 1+2 per year over the next 5 years | I25: Scope 1+2 carbon debt | J25: Scope 3 carbon debt
B26: =SLOPE(B28:B33,A28:A33)/B28 -> -0.01621843 | D26: =SLOPE(D34:D39,A34:A39)/D34 -> -0.096761349 | E26: =SLOPE(E28:E33,A28:A33)/E28 -> -0.0082142234 | F26: =SLOPE(F34:F39,A34:A39)/F33 -> -0.033096376 | I26: =SUM(I28:I33) -> 3909463.3 | J26: =SUM(J28:J33) -> 1.0201125e+08
A27: Year | B27: Reported S1+2 emissions | C27: S1+2 targets | D27: 1.5 pathway for scope 1+2 | E27: Scope 3 emissions | F27: 1.5 pathway for scope 3 | G27: S1+2 targets | I27: Scope 1+2 difference to pathway | J27: Scope 3 difference to pathway | M27: % reductions for Oil and Gas scope 1+2 emissions | N27: % reductions for Oil and Gas scope 3 emissions
A28: 2019 | B28: 44924200 | D28: =$B$28*M28 -> 44924200 | E28: 337019342 | F28: =$E$28*N28 -> 337019342 | I28: =B28-D28 -> 0 | J28: =E28-F28 -> 0 | M28: 1 | N28: 1
A29: 2020 | B29: 43651000 | D29: =$B$28*M29 -> 44506405 | E29: 322332479 | F29: =$E$28*N29 -> 3.2744799e+08 | I29: =B29-D29 -> -855404.94 | J29: =E29-F29 -> -5115513.7 | M29: 0.9907 | N29: 0.9716
A30: 2021 | B30: 41491000 | D30: =$B$28*M30 -> 44088610 | E30: 351541388 | F30: =$E$28*N30 -> 3.1787664e+08 | I30: =B30-D30 -> -2597609.9 | J30: =E30-F30 -> 33664745 | M30: 0.9814 | N30: 0.9432
A31: 2022 | B31: 46887000 | D31: =$B$28*M31 -> 43670815 | E31: 324352315 | F31: =$E$28*N31 -> 3.0830529e+08 | I31: =B31-D31 -> 3216185.2 | J31: =E31-F31 -> 16047021 | M31: 0.9721 | N31: 0.9148
A32: 2023 | B32: 41819000 | D32: =$B$28*M32 -> 40395841 | E32: 322167663 | F32: =$E$28*N32 -> 2.9873394e+08 | I32: =B32-D32 -> 1423159.4 | J32: =E32-F32 -> 23433718 | M32: 0.8992 | N32: 0.8864
A33: 2024 | B33: 39844000 | D33: =$B$28*M33 -> 37120866 | E33: 323177581 | F33: =$E$28*N33 -> 2.891963e+08 | I33: =B33-D33 -> 2723133.5 | J33: =E33-F33 -> 33981284 | M33: 0.8263 | N33: 0.8581
A34: 2025 | D34: =$B$28*M34 -> 33845892 | F34: =$E$28*N34 -> 2.7962495e+08 | M34: 0.7534 | N34: 0.8297
A35: 2026 | D35: =$B$28*M35 -> 30570918 | F35: =$E$28*N35 -> 2.700536e+08 | M35: 0.6805 | N35: 0.8013
A36: 2027 | D36: =$B$28*M36 -> 27295944 | F36: =$E$28*N36 -> 2.6048225e+08 | M36: 0.6076 | N36: 0.7729
A37: 2028 | D37: =$B$28*M37 -> 24020970 | F37: =$E$28*N37 -> 2.509109e+08 | M37: 0.5347 | N37: 0.7445
A38: 2029 | D38: =$B$28*M38 -> 20745996 | F38: =$E$28*N38 -> 2.4133955e+08 | M38: 0.4618 | N38: 0.7161
A39: 2030 | C39: =(1-E18)*F18 -> 38717600 | D39: =$B$28*M39 -> 17471021 | F39: =$E$28*N39 -> 2.317682e+08 | M39: 0.3889 | N39: 0.6877
A40: 2031 | D40: =$B$28*M40 -> 16815128 | F40: =$E$28*N40 -> 2.0332377e+08 | M40: 0.3743 | N40: 0.6033
A41: 2032 | D41: =$B$28*M41 -> 16159235 | F41: =$E$28*N41 -> 1.7487934e+08 | M41: 0.3597 | N41: 0.5189
A42: 2033 | D42: =$B$28*M42 -> 15503341 | F42: =$E$28*N42 -> 1.464349e+08 | M42: 0.3451 | N42: 0.4345
A43: 2034 | D43: =$B$28*M43 -> 14847448 | F43: =$E$28*N43 -> 1.1799047e+08 | M43: 0.3305 | N43: 0.3501
A44: 2035 | D44: =$B$28*M44 -> 14191555 | F44: =$E$28*N44 -> 89546039 | M44: 0.3159 | N44: 0.2657
A45: 2036 | D45: =$B$28*M45 -> 13540154 | F45: =$E$28*N45 -> 78424401 | M45: 0.3014 | N45: 0.2327
...

Sheet Severstal
A1: Main reporting sources
A2: Sustainbility report | B2: Integrated report | D2: Note on current sustainability disclosure | E2: Source
A3: Sustainability reports | B3: Sustainability reports | D3: Severstal has yet to publish its 2025 integrated report but its expected to do so in Q3 2026. The last dedicated climate report dates from 2022 but the copmany continues publishing relevant climate data via its annual integrated report. | E3: Sustainable Development Approach
A6: Emissions profile and disclosure
A7: Category | B7: Tons CO2e | C7: Year | D7: Disclosure framework | E7: Verification | G7: S1+2 share | H7: S3 share
A8: Scope 1 | B8: 23030000 | C8: 2024 | D8: GHG protocol | E8: External limited assurance | G8: =B10/B17 -> 0.65840903 | H8: =B16/B17 -> 0.34159097
A9: Scope 2 | B9: 890000 | C9: 2024 | D9: GHG protocol | E9: External limited assurance
A10: Scope 1+2 | B10: =SUM(B8:B9) -> 23920000 | C10: 2024 | D10: GHG protocol | E10: External limited assurance
A11: Capital goods | B11: 410000 | C11: 2024 | D11: GHG protocol | E11: External limited assurance
A12: Purchased goods and services | B12: 7390000 | C12: 2024 | D12: GHG protocol | E12: External limited assurance
A13: Upstream transportation and distribution | B13: 390000 | C13: 2024 | D13: GHG protocol | E13: External limited assurance
A14: Fuel and energy (not in S1+2) | B14: 1670000 | C14: 2024 | D14: GHG protocol | E14: External limited assurance
A15: Processing of sold products | B15: 2550000 | C15: 2024 | D15: GHG protocol | E15: External limited assurance
A16: Scope 3 | B16: =SUM(B11:B15) -> 12410000 | C16: 2024 | D16: GHG protocol | E16: External limited assurance
A17: Total 1+2+3 | B17: =SUM(B10,B16) -> 36330000 | C17: 2024 | D17: GHG protocol
A19: Climate targets
A20: Company | B20: Scope | C20: Base year | D20: Target tear | E20: % reduction | F20: Base emissions | G20: Target emissions | H20: Target type | I20: SBTi validation | J20: Scorable | K20: Activity unit | L20: Intensity unit | M20: Target wording
A21: Lukoil | B21: S1+2 | C21: 2020 | D21: 2030 | E21: 0.1 | F21: 24185400 | G21: 24513019 | H21: Intensity | I21: Not validated | J21: Valid | K21: Tonnes crude steel | L21: Tonnes crude steel | M21: Severstal’s Decarbonisation Strategy sets forth voluntary obligations to reduce the CO2 intensity of steel production by 3% in 2024 (short-term goal) and by 10% in 2030 (mid-term goal) against the 2020 baseline.
A22: Lukoil | B22: S1+2 | J22: Undisclosed | K22: metric tons
A23: Lukoil | B23: S3 | J23: Undisclosed | K23: metric tons
A24: Lukoil | B24: S3 | J24: Undisclosed | K24: metric tons
A27: Target appraisal
B28: Observed change per year in Scope 1+2 emissions | D28: Required reductions of scope 1+2 per year over the next 5 years | I28: Scope 1+2 carbon debt | J28: Scope 3 carbon debt
B29: =SLOPE(B31:B36,A31:A36)/B31 -> -0.030878691 | D29: =SLOPE(D37:D42,A37:A42)/D37 -> -0.068322655 | E29: =SLOPE(E31:E36,A31:A36)/E31 -> -0.037355525 | F29: =SLOPE(F37:F42,A37:A42)/F36 -> -0.054878115 | I29: =SUM(I31:I36) -> 11200701 | J29: =SUM(J31:J36) -> 2039155
A30: Year | B30: Reported S1+2 emissions | C30: S1+2 targets | D30: 1.5 pathway for scope 1+2 | E30: Scope 3 emissions | F30: 1.5 pathway for scope 3 | G30: S3 targets | I30: Scope 1+2 difference to pathway | J30: Scope 3 difference to pathway | M30: % reductions for Steel scope 1+2 emissions | N30: Corss sectoral Scope 3 % reductions pathway
A31: 2019 | B31: 28110000 | D31: =$B$31*M31 -> 28110000 | E31: 15450000 | F31: =$E$31*N31 -> 15450000 | I31: =B31-D31 -> 0 | J31: =E31-F31 -> 0 | M31: 1 | N31: 1
A32: 2020 | B32: 27860000 | D32: =$B$31*M32 -> 26988411 | E32: 16100000 | F32: =$E$31*N32 -> 14784105 | I32: =B32-D32 -> 871589 | J32: =E32-F32 -> 1315895 | M32: 0.9601 | N32: 0.9569
A33: 2021 | B33: 30270000 | D33: =$B$31*M33 -> 25864011 | E33: 14080000 | F33: =$E$31*N33 -> 14119755 | I33: =B33-D33 -> 4405989 | J33: =E33-F33 -> -39755 | M33: 0.9201 | N33: 0.9139
A34: 2022 | B34: 27080000 | D34: =$B$31*M34 -> 24742422 | E34: 12470000 | F34: =$E$31*N34 -> 13453860 | I34: =B34-D34 -> 2337578 | J34: =E34-F34 -> -983860 | M34: 0.8802 | N34: 0.8708
A35: 2023 | B35: 25780000 | D35: =$B$31*M35 -> 23618022 | E35: 13170000 | F35: =$E$31*N35 -> 12789510 | I35: =B35-D35 -> 2161978 | J35: =E35-F35 -> 380490 | M35: 0.8402 | N35: 0.8278
A36: 2024 | B36: 23920000 | D36: =$B$31*M36 -> 22496433 | E36: 13490000 | F36: =$E$31*N36 -> 12123615 | I36: =B36-D36 -> 1423567 | J36: =E36-F36 -> 1366385 | M36: 0.8003 | N36: 0.7847
A37: 2025 | D37: =$B$31*M37 -> 21372033 | F37: =$E$31*N37 -> 11457720 | M37: 0.7603 | N37: 0.7416
A38: 2026 | D38: =$B$31*M38 -> 19913124 | F38: =$E$31*N38 -> 10793370 | M38: 0.7084 | N38: 0.6986
A39: 2027 | D39: =$B$31*M39 -> 18451404 | F39: =$E$31*N39 -> 10127475 | M39: 0.6564 | N39: 0.6555
A40: 2028 | D40: =$B$31*M40 -> 16992495 | F40: =$E$31*N40 -> 9461580 | M40: 0.6045 | N40: 0.6124
A41: 2029 | D41: =$B$31*M41 -> 15530775 | F41: =$E$31*N41 -> 8797230 | M41: 0.5525 | N41: 0.5694
A42: 2030 | C42: =(1-E21)*F21 -> 21766860 | D42: =$B$31*M42 -> 14071866 | F42: =$E$31*N42 -> 8131335 | M42: 0.5006 | N42: 0.5263
A43: 2031 | D43: =$B$31*M43 -> 13144236 | F43: =$E$31*N43 -> 7629210 | M43: 0.4676 | N43: 0.4938
A44: 2032 | D44: =$B$31*M44 -> 12216606 | F44: =$E$31*N44 -> 7125540 | M44: 0.4346 | N44: 0.4612
A45: 2033 | D45: =$B$31*M45 -> 11288976 | F45: =$E$31*N45 -> 6623415 | M45: 0.4016 | N45: 0.4287
...
